<?xml version="1.0"?>
<robot name="gurdy">

    <material name="blue">
        <color rgba="0 0 0.8 1"/>
    </material>
    <material name="red">
        <color rgba="0.8 0 0 1"/>
    </material>
    <material name="green">
        <color rgba="0 0.8 0 1"/>
    </material> 

    <gazebo>
        <plugin name="gazebo_ros_control" filename="libgazebo_ros_control.so">
            <robotNamespace>/gurdy</robotNamespace>
        </plugin>
    </gazebo>

<!-- BASE & HEAD LINK -->
    <link name="base_link">
        <visual>
            <origin rpy="0 0 0" xyz="0 0 0"/>
            <geometry>
                <box size="0.01 0.01 0.01"/>
            </geometry>
            
        </visual>
    </link>

    <link name="head_link">

    <inertial>
        <origin xyz="0 0 0" rpy="0 0 0"/>
        <mass value="0.01" />
        <inertia ixx="7.5833333e-06" ixy="0.0" ixz="0.0" iyy="7.5833333e-06" iyz="0.0" izz="1.25e-05"/>
    </inertial>

    <collision>
        <origin xyz="0 0 0" rpy="0 0 0"/>
            <geometry>
                <cylinder radius="0.05" length="0.04"/>
            </geometry>
    </collision>


    <visual>
        <origin rpy="0 0 0" xyz="0 0 0"/>
        <geometry>
           <!--<cylinder radius="0.05" length="0.04"/> --> 

            <mesh filename="package://my_gurdy_description/models/gurdy/meshes/gurdy_head_v2.dae"/>
        </geometry>
        </visual>
    </link>
  
   <joint name="fixed" type="fixed">
        <parent link="base_link"/>
        <child link="head_link"/>
        <origin xyz="0 0 0" rpy="0 0 0"/>
    </joint>

    <!-- 1st Leg  -->

    <link name="upperlegM1_link">

    <inertial>
        <origin xyz="0 0 0" rpy="0 0 0"/>
        <mass value="0.01" />
        <inertia ixx="3.015625e-06" ixy="0.0" ixz="0.0" iyy="3.015625e-06" iyz="0.0" izz="3.1250e-08"/>
    </inertial>

    <collision>
        <origin xyz="0 0 0" rpy="0 0 0"/>
            <geometry>
                <cylinder radius="0.0025" length="0.06"/>
            </geometry>
    </collision>

        <visual>
            <origin rpy="0 0 0" xyz="0 0 0"/>
            <geometry>
                <!-- <cylinder length="0.06" radius="0.0025"/> -->
                <mesh filename="package://my_gurdy_description/models/gurdy/meshes/gurdy_higherleg_v2.dae"/>
            </geometry>
        </visual>
    </link>
    <gazebo reference="upperlegM1_link">
        <kp>1000.0</kp>
        <kd>1000.0</kd>
        <mu1>10.0</mu1>
        <mu2>10.0</mu2>
        <material>Gazebo/Red</material>
    </gazebo>    

    <joint name="head_upperlegM1_joint" type="revolute">
        <parent link="head_link"/>
        <child link="upperlegM1_link"/>
        <origin xyz="-0.02165 -0.0125 -0.008" rpy="3.14159 -1.05879e-22 0.523599"/>
        <limit lower="-1.55" upper="0.0" effort="1.0" velocity="0.005"/>
        <axis xyz="0 1 0"/>
    </joint>
  

      <transmission name="tran1">
        <type>transmission_interface/SimpleTransmission</type>
        <joint name="head_upperlegM1_joint">
            <hardwareInterface>hardware_interface/EffortJointInterface</hardwareInterface>
        </joint>
        <actuator name="motor1">
            <hardwareInterface>hardware_interface/EffortJointInterface</hardwareInterface>
            <mechanicalReduction>1</mechanicalReduction>
        </actuator>
    </transmission>

      <!-- 2nd Leg  -->

    <link name="upperlegM2_link">

    <inertial>
        <origin xyz="0 0 0" rpy="0 0 0"/>
        <mass value="0.01" />
        <inertia ixx="3.015625e-06" ixy="0.0" ixz="0.0" iyy="3.015625e-06" iyz="0.0" izz="3.1250e-08"/>
    </inertial>

    <collision>
        <origin xyz="0 0 0" rpy="0 0 0"/>
            <geometry>
                <cylinder radius="0.0025" length="0.06"/>
            </geometry>
    </collision> 

        <visual>
            <origin rpy="0 0 0" xyz="0 0 0"/>
            <geometry>
                <!-- <cylinder length="0.06" radius="0.0025"/> -->
                <mesh filename="package://my_gurdy_description/models/gurdy/meshes/gurdy_higherleg_v2.dae"/>
            </geometry>
        </visual>
    </link>

    <gazebo reference="upperlegM2_link">
        <kp>1000.0</kp>
        <kd>1000.0</kd>
        <mu1>10.0</mu1>
        <mu2>10.0</mu2>
        <material>Gazebo/Green</material>
    </gazebo>    

    <joint name="head_upperlegM2_joint" type="revolute">
        <parent link="head_link"/>
        <child link="upperlegM2_link"/>
        <origin xyz="0.02165 -0.0125 -0.008" rpy="3.14159 0 2.61799"/>
        <limit lower="-1.55" upper="0.0" effort="1.0" velocity="0.005"/>
        <axis xyz="0 1 0"/>
    </joint>

    <transmission name="tran2">
        <type>transmission_interface/SimpleTransmission</type>
        <joint name="head_upperlegM2_joint">
            <hardwareInterface>hardware_interface/EffortJointInterface</hardwareInterface>
        </joint>
        <actuator name="motor2">
            <hardwareInterface>hardware_interface/EffortJointInterface</hardwareInterface>
            <mechanicalReduction>1</mechanicalReduction>
        </actuator>
    </transmission>

        <!-- 3rd Leg  -->

    <link name="upperlegM3_link">
        <inertial>
        <origin xyz="0 0 0" rpy="0 0 0"/>
        <mass value="0.01" />
        <inertia ixx="3.015625e-06" ixy="0.0" ixz="0.0" iyy="3.015625e-06" iyz="0.0" izz="3.1250e-08"/>
    </inertial>

    <collision>
        <origin xyz="0 0 0" rpy="0 0 0"/>
            <geometry>
                <cylinder radius="0.0025" length="0.06"/>
            </geometry>
    </collision>

        <visual>
            <origin rpy="0 0 0" xyz="0 0 0"/>
            <geometry>
                <!-- <cylinder length="0.06" radius="0.0025"/> -->
                <mesh filename="package://my_gurdy_description/models/gurdy/meshes/gurdy_higherleg_v2.dae"/>
            </geometry>
        </visual>
    </link>

    <gazebo reference="upperlegM3_link">
        <kp>1000.0</kp>
        <kd>1000.0</kd>
        <mu1>10.0</mu1>
        <mu2>10.0</mu2>
        <material>Gazebo/Blue</material>
    </gazebo>    

    <joint name="head_upperlegM3_joint" type="revolute">
        <parent link="head_link"/>
        <child link="upperlegM3_link"/>
        <origin xyz="0 0.025 -0.008" rpy="3.14159 -0 -1.5708"/>
        <limit lower="-1.55" upper="0.0" effort="1.0" velocity="0.005"/>
        <axis xyz="0 1 0"/>
    </joint>

    <transmission name="tran3">
        <type>transmission_interface/SimpleTransmission</type>
        <joint name="head_upperlegM3_joint">
            <hardwareInterface>hardware_interface/EffortJointInterface</hardwareInterface>
        </joint>
        <actuator name="motor3">
            <hardwareInterface>hardware_interface/EffortJointInterface</hardwareInterface>
            <mechanicalReduction>1</mechanicalReduction>
        </actuator>
    </transmission>

    <!-- 1st lower Leg  -->

    <link name="lowerlegM1_link">

        <inertial>
        <origin xyz="0 0 0" rpy="0 0 0"/>
        <mass value="0.01" />
        <inertia ixx="3.005625e-06" ixy="0.0" ixz="0.0" iyy="3.005625e-06" iyz="0.0" izz="1.125e-08"/>
    </inertial>

    <collision>
        <origin xyz="0 0 0" rpy="0 0 0"/>
            <geometry>
                <cylinder radius="0.0015" length="0.06"/>
            </geometry>
    </collision>

        <visual>
            <origin rpy="0 0 0" xyz="0 0 0"/>
            <geometry>
                <!--<cylinder length="0.06" radius="0.0015"/>-->
                
                <mesh filename="package://my_gurdy_description/models/gurdy/meshes/gurdy_lowerleg_v2.dae"/>
            </geometry>
        </visual>
    </link>

    <gazebo reference="lowerlegM1_link">
        <kp>1000.0</kp>
        <kd>1000.0</kd>
        <mu1>10.0</mu1>
        <mu2>10.0</mu2>
        <material>Gazebo/Red</material>
    </gazebo>    

    <joint name="upperlegM1_lowerlegM1_joint" type="revolute">
        <parent link="upperlegM1_link"/>
        <child link="lowerlegM1_link"/>
        <origin xyz="0 0.0095 0.06" rpy="0 0 3.14159"/>
        <limit lower="-2.9" upper="1.5708" effort="1.0" velocity="0.005"/>
        <axis xyz="0 1 0"/>
    </joint>

    <transmission name="tran4">
        <type>transmission_interface/SimpleTransmission</type>
        <joint name="upperlegM1_lowerlegM1_joint">
            <hardwareInterface>hardware_interface/EffortJointInterface</hardwareInterface>
        </joint>
        <actuator name="motor4">
            <hardwareInterface>hardware_interface/EffortJointInterface</hardwareInterface>
            <mechanicalReduction>1</mechanicalReduction>
        </actuator>
    </transmission>
        <!-- 2nd lower Leg  -->

    <link name="lowerlegM2_link">

            <inertial>
        <origin xyz="0 0 0" rpy="0 0 0"/>
        <mass value="0.01" />
        <inertia ixx="3.005625e-06" ixy="0.0" ixz="0.0" iyy="3.005625e-06" iyz="0.0" izz="1.125e-08"/>
    </inertial>

    <collision>
        <origin xyz="0 0 0" rpy="0 0 0"/>
            <geometry>
                <cylinder radius="0.0015" length="0.06"/>
            </geometry>
    </collision>

        <visual>
            <origin rpy="0 0 0" xyz="0 0 0"/>
            <geometry>
                <!--<cylinder length="0.06" radius="0.0015"/>-->
                
                <mesh filename="package://my_gurdy_description/models/gurdy/meshes/gurdy_lowerleg_v2.dae"/>
            </geometry>
        </visual>
    </link>
    <gazebo reference="lowerlegM2_link">
        <kp>1000.0</kp>
        <kd>1000.0</kd>
        <mu1>10.0</mu1>
        <mu2>10.0</mu2>
        <material>Gazebo/Green</material>
    </gazebo>    

    <joint name="upperlegM2_lowerlegM2_joint" type="revolute">
        <parent link="upperlegM2_link"/>
        <child link="lowerlegM2_link"/>
        <origin xyz="0 0.0095 0.06" rpy="0 0 3.14159"/>
        <limit lower="-2.9" upper="1.5708" effort="1.0" velocity="0.005"/>
        <axis xyz="0 1 0"/>
    </joint>


    <transmission name="tran5">
        <type>transmission_interface/SimpleTransmission</type>
        <joint name="upperlegM2_lowerlegM2_joint">
            <hardwareInterface>hardware_interface/EffortJointInterface</hardwareInterface>
        </joint>
        <actuator name="motor5">
            <hardwareInterface>hardware_interface/EffortJointInterface</hardwareInterface>
            <mechanicalReduction>1</mechanicalReduction>
        </actuator>
    </transmission>

        <!-- 3rd lower Leg  -->

    <link name="lowerlegM3_link">

    <inertial>
        <origin xyz="0 0 0" rpy="0 0 0"/>
        <mass value="0.01" />
        <inertia ixx="3.005625e-06" ixy="0.0" ixz="0.0" iyy="3.005625e-06" iyz="0.0" izz="1.125e-08"/>
    </inertial>

    <collision>
        <origin xyz="0 0 0" rpy="0 0 0"/>
            <geometry>
                <cylinder radius="0.0015" length="0.06"/>
            </geometry>
    </collision>

        <visual>
            <origin rpy="0 0 0" xyz="0 0 0"/>
            <geometry>
                 <!--<cylinder length="0.06" radius="0.0015"/>-->
                
                <mesh filename="package://my_gurdy_description/models/gurdy/meshes/gurdy_lowerleg_v2.dae"/>
            </geometry>
        </visual>
    </link>
    <gazebo reference="lowerlegM3_link">
        <kp>1000.0</kp>
        <kd>1000.0</kd>
        <mu1>10.0</mu1>
        <mu2>10.0</mu2>
        <material>Gazebo/Blue</material>
    </gazebo>
    <joint name="upperlegM3_lowerlegM3_joint" type="revolute">
        <parent link="upperlegM3_link"/>
        <child link="lowerlegM3_link"/>
        <origin xyz="0 0.0095 0.06" rpy="0 0 3.14159"/>
        <limit lower="-2.9" upper="1.5708" effort="1.0" velocity="0.005"/>
        <axis xyz="0 1 0"/>
    </joint>

    <transmission name="tran6">
        <type>transmission_interface/SimpleTransmission</type>
        <joint name="upperlegM3_lowerlegM3_joint">
            <hardwareInterface>hardware_interface/EffortJointInterface</hardwareInterface>
        </joint>
        <actuator name="motor6">
            <hardwareInterface>hardware_interface/EffortJointInterface</hardwareInterface>
            <mechanicalReduction>1</mechanicalReduction>
        </actuator>
    </transmission>

        <!-- 1st foot  -->

    <link name="footM1_link">
    
    <inertial>
        <origin xyz="0 0 0" rpy="0 0 0"/>
        <mass value="0.01" />
        <inertia ixx="2.56e-07" ixy="0.0" ixz="0.0" iyy="2.56e-07" iyz="0.0" izz="2.56e-07"/>
    </inertial>

    <collision>
        <origin xyz="0 0 0" rpy="0 0 0"/>
            <geometry>
                <sphere radius="0.008"/>
            </geometry>
    </collision>

        <visual>
            <origin rpy="0 0 0" xyz="0 0 0"/>
            <geometry>
                <sphere radius="0.008"/>
            </geometry>
            <material name="red"/>
        </visual>
    </link>

      <gazebo reference="footM1_link">
        <kp>1000.0</kp>
        <kd>1000.0</kd>
        <mu1>10.0</mu1>
        <mu2>10.0</mu2>
        <material>Gazebo/Red</material>
    </gazebo>  

    <joint name="basefoot_peg_M1_basefoot_peg_M1_joint_joint" type="fixed">
        <parent link="lowerlegM1_link"/>
        <child link="footM1_link"/>
        <origin xyz="0 0 0.06" rpy="0 0 0"/>
    </joint>

        <!-- 2nd foot  -->

    <link name="footM2_link">

    <inertial>
        <origin xyz="0 0 0" rpy="0 0 0"/>
        <mass value="0.01" />
        <inertia ixx="2.56e-07" ixy="0.0" ixz="0.0" iyy="2.56e-07" iyz="0.0" izz="2.56e-07"/>
    </inertial>

    <collision>
        <origin xyz="0 0 0" rpy="0 0 0"/>
            <geometry>
                <sphere radius="0.008"/>
            </geometry>
    </collision>

        <visual>
            <origin rpy="0 0 0" xyz="0 0 0"/>
            <geometry>
                <sphere radius="0.008"/>
            </geometry>
            <material name="green"/>
        </visual>
    </link>

        <gazebo reference="footM2_link">
        <kp>1000.0</kp>
        <kd>1000.0</kd>
        <mu1>10.0</mu1>
        <mu2>10.0</mu2>
        <material>Gazebo/Green</material>
    </gazebo>
    
    <joint name="basefoot_peg_M2_basefoot_peg_M2_joint_joint" type="fixed">
        <parent link="lowerlegM2_link"/>
        <child link="footM2_link"/>
        <origin xyz="0 0 0.06" rpy="0 0 0"/>
    </joint>

            <!-- 3rd foot  -->

    <link name="footM3_link">

    <inertial>
        <origin xyz="0 0 0" rpy="0 0 0"/>
        <mass value="0.01" />
        <inertia ixx="2.56e-07" ixy="0.0" ixz="0.0" iyy="2.56e-07" iyz="0.0" izz="2.56e-07"/>
    </inertial>

    <collision>
        <origin xyz="0 0 0" rpy="0 0 0"/>
            <geometry>
                <sphere radius="0.008"/>
            </geometry>
    </collision>

        <visual>
            <origin rpy="0 0 0" xyz="0 0 0"/>
            <geometry>
               <sphere radius="0.008"/> 
              
            </geometry>
            <material name="blue"/>
        </visual>
    </link>

    <gazebo reference="footM3_link">
        <kp>1000.0</kp>
        <kd>1000.0</kd>
        <mu1>10.0</mu1>
        <mu2>10.0</mu2>
        <material>Gazebo/Blue</material>
    </gazebo>
    
    <joint name="basefoot_peg_M3_basefoot_peg_M3_joint_joint" type="fixed">
        <parent link="lowerlegM3_link"/>
        <child link="footM3_link"/>
        <origin xyz="0 0 0.06" rpy="0 0 0"/>
    </joint>


</robot>
