<?xml version="1.0"?>
<robot name="mira">

    <material name="green">
        <color rgba="0 0.8 0 1"/>
    </material>

    <material name="blue">
        <color rgba="0 0 0.8 1"/>
    </material>

    <link name="base_link">
        <visual>
        <origin rpy="0 0 0" xyz="0.5 0 0"/>
        <geometry>
            <sphere radius="0.06"/>
        </geometry>
        <material name="green"/>
        </visual>
    </link>
  
    <link name="roll_M1_link">
        <visual>
            <origin rpy="0 0 0" xyz="0 0 0"/>
            <geometry>
                <box size="0.07 0.07 0.07"/>
            </geometry>
            <material name="blue"/>
        </visual>
    </link>
    
    <joint name="roll_joint" type="prismatic">
        <parent link="base_link"/>
        <child link="roll_M1_link"/>
        <origin xyz="0.0023 0 -0.0005" rpy="0 0 0"/>
        <limit lower="-0.5" upper="0.8" effort="0.1" velocity="0.005"/>
        <axis xyz="1 0 1"/>
    </joint>
  
</robot>
